[2020-11-15T20:32:38] DEBUG [root.log_tofile:27] (<class 'pyodbc.InterfaceError'>, InterfaceError('IM002', '[IM002] [unixODBC][Driver Manager]Data source name not found and no default driver specified (0) (SQLDriverConnect)'), <traceback object at 0x1017ded80>)
